<?xml version="1.0"?>
<robot xmlns:xacro="http://www.ros.org/wiki/xacro">

  <!-- Wheels -->
  <xacro:property name="wheel_radius" value="0.125" />
  <xacro:property name="wheel_width" value="0.1" />
  <xacro:property name="wheel_mass" value="4.0" /><!-- in kg-->

  <!-- Steer wheel properties -->
  <xacro:property name="steer_joint_damping" value="1000" />
  <xacro:property name="steer_joint_friction" value="1000.0" />
  <xacro:property name="steer_joint_effort_limit" value="9999.0" />
  <xacro:property name="steer_joint_velocity_limit" value="20" />
  <xacro:property name="steer_mechanical_reduction" value="1.0" />
  <xacro:property name="steer_joint_position_limit" value="1.56" />

  <!-- Traction wheel properties -->
  <xacro:property name="traction_joint_damping" value="5" />
  <xacro:property name="traction_joint_friction" value="1000.0" />
  <xacro:property name="traction_joint_effort_limit" value="100000.0" />
  <xacro:property name="traction_joint_velocity_limit" value="100" />
  <xacro:property name="traction_mechanical_reduction" value="1.0" />


  <xacro:property name="steer_origin" value="0 0 -0.210"/>
  <xacro:property name="traction_origin" value="0 0 -0.335"/>

  <!-- inertial equation -->
  <xacro:macro name="cylinder_inertia" params="m r h">
    <inertia ixx="${m*(3*r*r+h*h)/12}" ixy = "0" ixz = "0" iyy="${m*(3*r*r+h*h)/12}" iyz = "0" izz="${m*r*r/2}" />
  </xacro:macro>

  <!-- *********** -->
  <!-- MOTOR WHEEL -->
  <!-- *********** -->
  <xacro:macro name="motor_wheel" params="prefix parent *origin hq">

    <!-- STEER -->
    <joint name="${prefix}wheel_steer_joint" type="revolute">
      <parent link="${parent}"/>
      <child link="${prefix}wheel_steer_link"/>
      <xacro:insert_block name="origin" />
      <axis xyz="0 0 1" rpy="0 0 0" />
      <limit effort="${steer_joint_effort_limit}" velocity="${steer_joint_velocity_limit}" lower="-${steer_joint_position_limit}" upper="${steer_joint_position_limit}"/>/>
      <dynamics damping="${steer_joint_damping}" friction="${steer_joint_friction}"/>
    </joint>

    <link name="${prefix}wheel_steer_link">
      <inertial>
        <mass value="${wheel_mass}" />
        <origin xyz="${steer_origin}"/>
        <cylinder_inertia m="${wheel_mass}" r="${wheel_width}" h="${wheel_radius}" />
      </inertial>
    </link>


    <!-- TRACTION -->
    <joint name="${prefix}wheel_traction_joint" type="continuous">
      <parent link="${prefix}wheel_steer_link"/>
      <child link="${prefix}wheel_traction_link"/>
      <origin xyz="${traction_origin}" rpy="0 0 0" />
      <axis xyz="0 1 0" rpy="0 0 0" />
      <limit effort="${traction_joint_effort_limit}" velocity="${traction_joint_velocity_limit}" />
      <dynamics damping="${traction_joint_damping}" friction="${traction_joint_friction}"/>
    </joint>


    <link name="${prefix}wheel_traction_link">
      <visual>
        <xacro:if value="${hq}">
          <origin xyz="0 0 -0.125" rpy="0 0 0" />
          <geometry>
            <mesh filename="package://hr_recycler_description/meshes/wheels/hr_recycler_wheel.stl" scale="1 -0.9 1"/>
          </geometry>
        </xacro:if>
        <xacro:unless value="${hq}">
          <origin xyz="0 0 -0.125" rpy="0 0 0" />
          <geometry>
            <mesh filename="package://hr_recycler_description/meshes/wheels/hr_recycler_wheel.stl" scale="1 -0.9 1"/>
          </geometry>
        </xacro:unless>
      </visual>
      <collision>
        <origin xyz="0 0 -0.125" rpy="0 0 0" />
        <geometry>
          <mesh filename="package://hr_recycler_description/meshes/wheels/hr_recycler_wheel.stl" scale="1 -0.9 1"/>
        </geometry>
      </collision>
      <inertial>
        <mass value="${wheel_mass}" />
        <origin xyz="0 0 0"/>
        <cylinder_inertia m="${wheel_mass}" r="${wheel_radius}" h="${wheel_width}" />
      </inertial>
    </link>


    <!-- ***************** -->
    <!-- GAZEBO PROPERTIES -->
    <!-- ***************** -->

    <!-- TRACTION LINK -->
    <gazebo reference="${prefix}wheel_traction_link">
      <mu1>3</mu1>
      <mu2>2</mu2>
      <material>Gazebo/Black</material>
    </gazebo>

    <!-- ************* -->
    <!-- TRANSMISSIONS -->
    <!-- ************* -->

    <!-- STEER -->
    <transmission name="${prefix}wheel_steer_trans">
      <type>transmission_interface/SimpleTransmission</type>
      <joint name="${prefix}wheel_steer_joint">
        <hardwareInterface>hardware_interface/PositionJointInterface</hardwareInterface>
      </joint>
      <actuator name="${prefix}wheel_steer_motor">
        <hardwareInterface>hardware_interface/PositionActuatorInterface</hardwareInterface>
        <mechanicalReduction>${steer_mechanical_reduction}</mechanicalReduction>
      </actuator>
    </transmission>

  <!-- TRACTION -->
    <transmission name="${prefix}wheel_traction">
      <type>transmission_interface/SimpleTransmission</type>
      <joint name="${prefix}wheel_traction_joint">
        <hardwareInterface>hardware_interface/VelocityJointInterface</hardwareInterface>
      </joint>
      <actuator name="${prefix}wheel_traction_motor">
        <hardwareInterface>hardware_interface/VelocityActuatorInterface</hardwareInterface>
        <mechanicalReduction>${traction_mechanical_reduction}</mechanicalReduction>
      </actuator>
    </transmission>

  </xacro:macro>
</robot>
