<?xml version="1.0"?>
<robot xmlns:xacro="http://wiki.ros.org/xacro">

  <!-- Wheels -->
  <xacro:property name="wheel_radius" value="0.122" />
  <xacro:property name="wheel_width" value="0.1" />
  <xacro:property name="wheel_mass" value="10" /><!-- in kg-->

  <!-- Steer wheel properties -->
  <xacro:property name="steer_joint_damping" value="1000" />
  <xacro:property name="steer_joint_friction" value="1000.0" />
  <xacro:property name="steer_joint_effort_limit" value="9999.0" />
  <xacro:property name="steer_joint_velocity_limit" value="20" />
  <xacro:property name="steer_mechanical_reduction" value="1.0" />
  <xacro:property name="steer_joint_position_limit" value="1.56" />

  <!-- Traction wheel properties -->
  <xacro:property name="traction_joint_damping" value="5" />
  <xacro:property name="traction_joint_friction" value="1000.0" />
  <xacro:property name="traction_joint_effort_limit" value="100000.0" />
  <xacro:property name="traction_joint_velocity_limit" value="100" />
  <xacro:property name="traction_mechanical_reduction" value="1.0" />


  <xacro:property name="steer_origin" value="0 0 ${wheel_radius}"/>
  <xacro:property name="front_wheel_origin" value="0 0 0"/>

  <!-- inertial equation -->
  <xacro:macro name="cylinder_inertia" params="m r h">
    <inertia  ixx="${m*(3*r*r+h*h)/12}" ixy = "0" ixz = "0"
              iyy="${m*r*r/2}" iyz = "0"
              izz="${m*(3*r*r+h*h)/12}"
     />
  </xacro:macro>

  <!-- *********** -->
  <!-- MOTOR WHEEL -->
  <!-- *********** -->
  <xacro:macro name="motor_wheel" params="prefix parent *origin">

    <!-- STEER -->
    <joint name="${prefix}steer_joint" type="revolute">
      <xacro:insert_block name="origin" />
      <parent link="${parent}"/>
      <child link="${prefix}steer_link"/>
      <axis xyz="0 0 1" rpy="0 0 0" />
      <limit effort="${steer_joint_effort_limit}" velocity="${steer_joint_velocity_limit}" lower="-${steer_joint_position_limit}" upper="${steer_joint_position_limit}"/>
      <dynamics damping="${steer_joint_damping}" friction="${steer_joint_friction}"/>
    </joint>

    <link name="${prefix}steer_link">
      <inertial>
        <mass value="${wheel_mass}" />
        <origin xyz="0 0 0"/>
        <cylinder_inertia m="${wheel_mass}" r="${wheel_width}" h="${wheel_radius}" />
      </inertial>
    </link>


    <!-- TRACTION -->
    <joint name="${prefix}traction_joint" type="continuous">
      <parent link="${prefix}steer_link"/>
      <child link="${prefix}front_wheel_link"/>
      <origin xyz="0 0 0" rpy="0 0 0" />
      <axis xyz="0 1 0" rpy="0 0 0" />
      <limit effort="${traction_joint_effort_limit}" velocity="${traction_joint_velocity_limit}" />
      <dynamics damping="${traction_joint_damping}" friction="${traction_joint_friction}"/>
    </joint>


    <link name="${prefix}front_wheel_link">
      <visual>
        <!--origin xyz="0 0 0" rpy="${PI/2.0} 0 0" /-->
        <origin xyz="0 0 0" rpy="0 0 0" />
        <geometry>
          <mesh filename="package://pallet_truck_description/meshes/wheels/pallet_truck_wheel.stl"/>
          <!--cylinder length="${wheel_width}" radius="${0.12675}"/-->
        </geometry>
      </visual>
      <collision>
        <!--origin xyz="0 0 0" rpy="0 0 0" /-->
        <origin xyz="0 0 0" rpy="${PI/2.0} 0 0" />
        <geometry>
          <!--mesh filename="package://pallet_truck_description/meshes/wheels/pallet_truck_wheel.stl"/-->
          <cylinder length="${wheel_width}" radius="${0.125}"/>
        </geometry>
      </collision>
      <inertial>
        <mass value="${wheel_mass}" />
        <origin xyz="0.000063 0 0.000465"/>
        <cylinder_inertia  m="${wheel_mass}" r="${wheel_radius}" h="${wheel_width}" />
      </inertial>
    </link>


    <!-- ***************** -->
    <!-- GAZEBO PROPERTIES -->
    <!-- ***************** -->

    <!-- TRACTION LINK -->
    <gazebo reference="${prefix}front_wheel_link">
      <mu1>1</mu1>
      <mu2>1</mu2>
      <kp>100000000</kp>
      <kd>10</kd>
      <material>Gazebo/Black</material>
    </gazebo>

    <!-- ************* -->
    <!-- TRANSMISSIONS -->
    <!-- ************* -->

    <!-- STEER -->
    <transmission name="${prefix}wheel_steer_trans">
      <type>transmission_interface/SimpleTransmission</type>
      <joint name="${prefix}steer_joint">
        <hardwareInterface>hardware_interface/PositionJointInterface</hardwareInterface>
      </joint>
      <actuator name="${prefix}steer_motor">
        <hardwareInterface>hardware_interface/PositionActuatorInterface</hardwareInterface>
        <mechanicalReduction>${steer_mechanical_reduction}</mechanicalReduction>
      </actuator>
    </transmission>

  <!-- TRACTION -->
    <transmission name="${prefix}_traction">
      <type>transmission_interface/SimpleTransmission</type>
      <joint name="${prefix}traction_joint">
        <hardwareInterface>hardware_interface/VelocityJointInterface</hardwareInterface>
      </joint>
      <actuator name="${prefix}traction_motor">
        <hardwareInterface>hardware_interface/VelocityActuatorInterface</hardwareInterface>
        <mechanicalReduction>${traction_mechanical_reduction}</mechanicalReduction>
      </actuator>
    </transmission>

  </xacro:macro>
</robot>
